<?xml version="1.0" encoding="UTF-8"?>
<!-- Generated by org.testng.reporters.JUnitReportReporter -->
<testsuite skipped="0" hostname="CPX-ANXXTNSGFUP" name="Test.ExpectedExceptionTest" tests="2" failures="0" timestamp="14 paÅº 2019 11:08:10 GMT" time="0.015" errors="1">
  <testcase name="testPrintMessage" time="0.011" classname="Test.ExpectedExceptionTest">
    <error type="org.testng.TestException" message="
Method ExpectedExceptionTest.testPrintMessage()[pri:0, instance:Test.ExpectedExceptionTest@5034c75a] should have thrown an exception of type class java.lang.ArithmeticException">
      <![CDATA[org.testng.TestException: 
Method ExpectedExceptionTest.testPrintMessage()[pri:0, instance:Test.ExpectedExceptionTest@5034c75a] should have thrown an exception of type class java.lang.ArithmeticException
at org.testng.internal.ExpectedExceptionsHolder.noException(ExpectedExceptionsHolder.java:80)
at org.testng.internal.Invoker.considerExceptions(Invoker.java:1139)
at org.testng.internal.Invoker.invokeMethod(Invoker.java:612)
at org.testng.internal.Invoker.invokeTestMethod(Invoker.java:716)
at org.testng.internal.Invoker.invokeTestMethods(Invoker.java:988)
at org.testng.internal.TestMethodWorker.invokeTestMethods(TestMethodWorker.java:125)
at org.testng.internal.TestMethodWorker.run(TestMethodWorker.java:109)
at org.testng.TestRunner.privateRun(TestRunner.java:648)
at org.testng.TestRunner.run(TestRunner.java:505)
at org.testng.SuiteRunner.runTest(SuiteRunner.java:455)
at org.testng.SuiteRunner.runSequentially(SuiteRunner.java:450)
at org.testng.SuiteRunner.privateRun(SuiteRunner.java:415)
at org.testng.SuiteRunner.run(SuiteRunner.java:364)
at org.testng.SuiteRunnerWorker.runSuite(SuiteRunnerWorker.java:52)
at org.testng.SuiteRunnerWorker.run(SuiteRunnerWorker.java:84)
at org.testng.TestNG.runSuitesSequentially(TestNG.java:1208)
at org.testng.TestNG.runSuitesLocally(TestNG.java:1137)
at org.testng.TestNG.runSuites(TestNG.java:1049)
at org.testng.TestNG.run(TestNG.java:1017)
at org.testng.remote.AbstractRemoteTestNG.run(AbstractRemoteTestNG.java:114)
at org.testng.remote.RemoteTestNG.initAndRun(RemoteTestNG.java:251)
at org.testng.remote.RemoteTestNG.main(RemoteTestNG.java:77)
]]>
    </error>
  </testcase> <!-- testPrintMessage -->
  <testcase name="testSalutationMessage" time="0.004" classname="Test.ExpectedExceptionTest"/>
</testsuite> <!-- Test.ExpectedExceptionTest -->
